Workbook

Sheet Supuestos
A1: IslaEncantada.com – Supuestos del modelo
A3: USUARIOS Y CRECIMIENTO
A4: Start_DAU | B4: 1500 | C4: Usuarios activos diarios promedio al mes 1
A5: Max_DAU | B5: 100000 | C5: Capacidad técnica máxima de usuarios activos diarios
A6: Organic_growth | B6: 0.06 | C6: Crecimiento orgánico mensual (6%)
A7: Improvement_growth | B7: 0.02 | C7: Extra de crecimiento por mejoras (+1% features) (2%)
A8: Days_per_month | B8: 30.4 | C8: Días promedio por mes
A10: MARKETING Y CAC
A11: Marketing_month1 | B11: 30000 | C11: Gasto de marketing mes 1 (USD)
A12: Marketing_growth | B12: 0.07 | C12: Crecimiento mensual del presupuesto de marketing (7%)
A13: Paid_CAC | B13: 18 | C13: CAC pagado objetivo (USD por usuario nuevo)
A15: MONETIZACIÓN POR USUARIO ACTIVO EN 24 HORAS
A16: Rev_room_per_user_per_day | B16: 35 | C16: Ingreso por 'habitación' virtual por usuario activo en 24h (USD)
A17: Rev_activities_per_user_per_day | B17: 15 | C17: Ingreso por actividades por usuario activo en 24h (USD)
A18: Rev_shops_per_user_per_day | B18: 5 | C18: Ingreso por tiendas/regalos por usuario activo en 24h (USD)
A20: COSTOS
A21: Var_cost_per_user_per_day | B21: 4 | C21: Costo variable (servidores, soporte, plataf.) por usuario activo en 24h (USD)
A22: Founder_salary | B22: 8000 | C22: Salario mensual fundador/director (USD)
A23: Env_artist_salary | B23: 5000 | C23: Salario mensual Environment Artist (USD)
A24: Tech_dev_salary | B24: 6000 | C24: Salario mensual Technical Developer (USD)
A25: Support_Ops_team_salary | B25: 6000 | C25: Salario mensual equipo soporte/operación (USD)
A26: Other_fixed_costs | B26: 6000 | C26: Otros costos fijos mensuales (herramientas, admin, etc.) (USD)
A28: CONFIGURACIÓN DEL MODELO
A29: Projection_months | B29: 60 | C29: Horizonte de proyección en meses
A31: ARPU_per_user_per_day | B31: =B16+B17+B18 -> 55 | C31: Ingreso promedio total por usuario activo en 24h (USD)

Sheet Proyeccion_60m
A1: IslaEncantada.com – Proyección mensual 60 meses (USD)
A3: Mes | B3: DAU_promedio | C3: Nuevos_usuarios_totales | D3: Nuevos_usuarios_pagados | E3: Nuevos_usuarios_organicos | F3: ARPU_dia_USD | G3: Ingresos_totales_USD | H3: Ingresos_habitaciones_USD | I3: Ingresos_actividades_USD | J3: Ingresos_tiendas_USD | K3: Costos_variables_USD | L3: Sueldos_fijos_USD | M3: Otros_fijos_USD | N3: Marketing_USD | O3: Costos_totales_USD | P3: Utilidad_mensual_USD | Q3: Utilidad_por_usuario_24h_USD | R3: CAC_mezclado_USD | S3: Margen_utilidad
A4: 1 | B4: =Supuestos!B4 -> 1500 | C4: =B4 -> 1500 | D4: =IF(Supuestos!B13>0,N4/Supuestos!B13,0) -> 1666.6667 | E4: =MAX(C4-D4,0) -> 0 | F4: =Supuestos!B31 -> 55 | G4: =H4+I4+J4 -> 2508000 | H4: =B4*Supuestos!B16*Supuestos!B8 -> 1596000 | I4: =B4*Supuestos!B17*Supuestos!B8 -> 684000 | J4: =B4*Supuestos!B18*Supuestos!B8 -> 228000 | K4: =B4*Supuestos!B21*Supuestos!B8 -> 182400 | L4: =Supuestos!B22+Supuestos!B23+Supuestos!B24+Supuestos!B25 -> 25000 | M4: =Supuestos!B26 -> 6000 | N4: =Supuestos!B11 -> 30000 | O4: =K4+L4+M4+N4 -> 243400 | P4: =G4-O4 -> 2264600 | Q4: =IF(B4*Supuestos!B8>0,P4/(B4*Supuestos!B8),0) -> 49.662281 | R4: =IF(C4>0,N4/C4,0) -> 20 | S4: =IF(G4>0,P4/G4,0) -> 0.90295056
A5: 2 | B5: =MIN(Supuestos!B5,B4*(1+Supuestos!B6+Supuestos!B7)+D5) -> 3403.3333 | C5: =B4*(Supuestos!B6+Supuestos!B7)+D5 -> 1903.3333 | D5: =IF(Supuestos!B13>0,N5/Supuestos!B13,0) -> 1783.3333 | E5: =MAX(C5-D5,0) -> 120 | F5: =Supuestos!B31 -> 55 | G5: =H5+I5+J5 -> 5690373.3 | H5: =B5*Supuestos!B16*Supuestos!B8 -> 3621146.7 | I5: =B5*Supuestos!B17*Supuestos!B8 -> 1551920 | J5: =B5*Supuestos!B18*Supuestos!B8 -> 517306.67 | K5: =B5*Supuestos!B21*Supuestos!B8 -> 413845.33 | L5: =Supuestos!B22+Supuestos!B23+Supuestos!B24+Supuestos!B25 -> 25000 | M5: =Supuestos!B26 -> 6000 | N5: =N4*(1+Supuestos!B12) -> 32100 | O5: =K5+L5+M5+N5 -> 476945.33 | P5: =G5-O5 -> 5213428 | Q5: =IF(B5*Supuestos!B8>0,P5/(B5*Supuestos!B8),0) -> 50.39011 | R5: =IF(C5>0,N5/C5,0) -> 16.865149 | S5: =IF(G5>0,P5/G5,0) -> 0.91618382
A6: 3 | B6: =MIN(Supuestos!B5,B5*(1+Supuestos!B6+Supuestos!B7)+D6) -> 5583.7667 | C6: =B5*(Supuestos!B6+Supuestos!B7)+D6 -> 2180.4333 | D6: =IF(Supuestos!B13>0,N6/Supuestos!B13,0) -> 1908.1667 | E6: =MAX(C6-D6,0) -> 272.26667 | F6: =Supuestos!B31 -> 55 | G6: =H6+I6+J6 -> 9336057.9 | H6: =B6*Supuestos!B16*Supuestos!B8 -> 5941127.7 | I6: =B6*Supuestos!B17*Supuestos!B8 -> 2546197.6 | J6: =B6*Supuestos!B18*Supuestos!B8 -> 848732.53 | K6: =B6*Supuestos!B21*Supuestos!B8 -> 678986.03 | L6: =Supuestos!B22+Supuestos!B23+Supuestos!B24+Supuestos!B25 -> 25000 | M6: =Supuestos!B26 -> 6000 | N6: =N5*(1+Supuestos!B12) -> 34347 | O6: =K6+L6+M6+N6 -> 744333.03 | P6: =G6-O6 -> 8591724.8 | Q6: =IF(B6*Supuestos!B8>0,P6/(B6*Supuestos!B8),0) -> 50.615032 | R6: =IF(C6>0,N6/C6,0) -> 15.752373 | S6: =IF(G6>0,P6/G6,0) -> 0.92027331
A7: 4 | B7: =MIN(Supuestos!B5,B6*(1+Supuestos!B6+Supuestos!B7)+D7) -> 8072.2063 | C7: =B6*(Supuestos!B6+Supuestos!B7)+D7 -> 2488.4397 | D7: =IF(Supuestos!B13>0,N7/Supuestos!B13,0) -> 2041.7383 | E7: =MAX(C7-D7,0) -> 446.70133 | F7: =Supuestos!B31 -> 55 | G7: =H7+I7+J7 -> 13496729 | H7: =B7*Supuestos!B16*Supuestos!B8 -> 8588827.5 | I7: =B7*Supuestos!B17*Supuestos!B8 -> 3680926.1 | J7: =B7*Supuestos!B18*Supuestos!B8 -> 1226975.4 | K7: =B7*Supuestos!B21*Supuestos!B8 -> 981580.29 | L7: =Supuestos!B22+Supuestos!B23+Supuestos!B24+Supuestos!B25 -> 25000 | M7: =Supuestos!B26 -> 6000 | N7: =N6*(1+Supuestos!B12) -> 36751.29 | O7: =K7+L7+M7+N7 -> 1049331.6 | P7: =G7-O7 -> 12447397 | Q7: =IF(B7*Supuestos!B8>0,P7/(B7*Supuestos!B8),0) -> 50.723909 | R7: =IF(C7>0,N7/C7,0) -> 14.768809 | S7: =IF(G7>0,P7/G7,0) -> 0.9222529
A8: 5 | B8: =MIN(Supuestos!B5,B7*(1+Supuestos!B6+Supuestos!B7)+D8) -> 10902.643 | C8: =B7*(Supuestos!B6+Supuestos!B7)+D8 -> 2830.4365 | D8: =IF(Supuestos!B13>0,N8/Supuestos!B13,0) -> 2184.66 | E8: =MAX(C8-D8,0) -> 645.77651 | F8: =Supuestos!B31 -> 55 | G8: =H8+I8+J8 -> 18229219 | H8: =B8*Supuestos!B16*Supuestos!B8 -> 11600412 | I8: =B8*Supuestos!B17*Supuestos!B8 -> 4971605.1 | J8: =B8*Supuestos!B18*Supuestos!B8 -> 1657201.7 | K8: =B8*Supuestos!B21*Supuestos!B8 -> 1325761.4 | L8: =Supuestos!B22+Supuestos!B23+Supuestos!B24+Supuestos!B25 -> 25000 | M8: =Supuestos!B26 -> 6000 | N8: =N7*(1+Supuestos!B12) -> 39323.88 | O8: =K8+L8+M8+N8 -> 1396085.3 | P8: =G8-O8 -> 16833134 | Q8: =IF(B8*Supuestos!B8>0,P8/(B8*Supuestos!B8),0) -> 50.787823 | R8: =IF(C8>0,N8/C8,0) -> 13.893221 | S8: =IF(G8>0,P8/G8,0) -> 0.92341497
A9: 6 | B9: =MIN(Supuestos!B5,B8*(1+Supuestos!B6+Supuestos!B7)+D9) -> 14112.441 | C9: =B8*(Supuestos!B6+Supuestos!B7)+D9 -> 3209.7976 | D9: =IF(Supuestos!B13>0,N9/Supuestos!B13,0) -> 2337.5862 | E9: =MAX(C9-D9,0) -> 872.21143 | F9: =Supuestos!B31 -> 55 | G9: =H9+I9+J9 -> 23596001 | H9: =B9*Supuestos!B16*Supuestos!B8 -> 15015637 | I9: =B9*Supuestos!B17*Supuestos!B8 -> 6435272.9 | J9: =B9*Supuestos!B18*Supuestos!B8 -> 2145091 | K9: =B9*Supuestos!B21*Supuestos!B8 -> 1716072.8 | L9: =Supuestos!B22+Supuestos!B23+Supuestos!B24+Supuestos!B25 -> 25000 | M9: =Supuestos!B26 -> 6000 | N9: =N8*(1+Supuestos!B12) -> 42076.552 | O9: =K9+L9+M9+N9 -> 1789149.3 | P9: =G9-O9 -> 21806851 | Q9: =IF(B9*Supuestos!B8>0,P9/(B9*Supuestos!B8),0) -> 50.829666 | R9: =IF(C9>0,N9/C9,0) -> 13.108786 | S9: =IF(G9>0,P9/G9,0) -> 0.92417574
A10: 7 | B10: =MIN(Supuestos!B5,B9*(1+Supuestos!B6+Supuestos!B7)+D10) -> 17742.653 | C10: =B9*(Supuestos!B6+Supuestos!B7)+D10 -> 3630.2125 | D10: =IF(Supuestos!B13>0,N10/Supuestos!B13,0) -> 2501.2173 | E10: =MAX(C10-D10,0) -> 1128.9952 | F10: =Supuestos!B31 -> 55 | G10: =H10+I10+J10 -> 29665716 | H10: =B10*Supuestos!B16*Supuestos!B8 -> 18878183 | I10: =B10*Supuestos!B17*Supuestos!B8 -> 8090649.8 | J10: =B10*Supuestos!B18*Supuestos!B8 -> 2696883.3 | K10: =B10*Supuestos!B21*Supuestos!B8 -> 2157506.6 | L10: =Supuestos!B22+Supuestos!B23+Supuestos!B24+Supuestos!B25 -> 25000 | M10: =Supuestos!B26 -> 6000 | N10: =N9*(1+Supuestos!B12) -> 45021.911 | O10: =K10+L10+M10+N10 -> 2233528.5 | P10: =G10-O10 -> 27432187 | Q10: =IF(B10*Supuestos!B8>0,P10/(B10*Supuestos!B8),0) -> 50.859056 | R10: =IF(C10>0,N10/C10,0) -> 12.402004 | S10: =IF(G10>0,P10/G10,0) -> 0.92471011
A11: 8 | B11: =MIN(Supuestos!B5,B10*(1+Supuestos!B6+Supuestos!B7)+D11) -> 21838.368 | C11: =B10*(Supuestos!B6+Supuestos!B7)+D11 -> 4095.7147 | D11: =IF(Supuestos!B13>0,N11/Supuestos!B13,0) -> 2676.3025 | E11: =MAX(C11-D11,0) -> 1419.4122 | F11: =Supuestos!B31 -> 55 | G11: =H11+I11+J11 -> 36513751 | H11: =B11*Supuestos!B16*Supuestos!B8 -> 23236023 | I11: =B11*Supuestos!B17*Supuestos!B8 -> 9958295.7 | J11: =B11*Supuestos!B18*Supuestos!B8 -> 3319431.9 | K11: =B11*Supuestos!B21*Supuestos!B8 -> 2655545.5 | L11: =Supuestos!B22+Supuestos!B23+Supuestos!B24+Supuestos!B25 -> 25000 | M11: =Supuestos!B26 -> 6000 | N11: =N10*(1+Supuestos!B12) -> 48173.444 | O11: =K11+L11+M11+N11 -> 2734719 | P11: =G11-O11 -> 33779032 | Q11: =IF(B11*Supuestos!B8>0,P11/(B11*Supuestos!B8),0) -> 50.880742 | R11: =IF(C11>0,N11/C11,0) -> 11.761914 | S11: =IF(G11>0,P11/G11,0) -> 0.92510441
A12: 9 | B12: =MIN(Supuestos!B5,B11*(1+Supuestos!B6+Supuestos!B7)+D12) -> 26449.081 | C12: =B11*(Supuestos!B6+Supuestos!B7)+D12 -> 4610.713 | D12: =IF(Supuestos!B13>0,N12/Supuestos!B13,0) -> 2863.6436 | E12: =MAX(C12-D12,0) -> 1747.0694 | F12: =Supuestos!B31 -> 55 | G12: =H12+I12+J12 -> 44222863 | H12: =B12*Supuestos!B16*Supuestos!B8 -> 28141822 | I12: =B12*Supuestos!B17*Supuestos!B8 -> 12060781 | J12: =B12*Supuestos!B18*Supuestos!B8 -> 4020260.3 | K12: =B12*Supuestos!B21*Supuestos!B8 -> 3216208.2 | L12: =Supuestos!B22+Supuestos!B23+Supuestos!B24+Supuestos!B25 -> 25000 | M12: =Supuestos!B26 -> 6000 | N12: =N11*(1+Supuestos!B12) -> 51545.585 | O12: =K12+L12+M12+N12 -> 3298753.8 | P12: =G12-O12 -> 40924109 | Q12: =IF(B12*Supuestos!B8>0,P12/(B12*Supuestos!B8),0) -> 50.897338 | R12: =IF(C12>0,N12/C12,0) -> 11.179526 | S12: =IF(G12>0,P12/G12,0) -> 0.92540615
A13: 10 | B13: =MIN(Supuestos!B5,B12*(1+Supuestos!B6+Supuestos!B7)+D13) -> 31629.106 | C13: =B12*(Supuestos!B6+Supuestos!B7)+D13 -> 5180.0251 | D13: =IF(Supuestos!B13>0,N13/Supuestos!B13,0) -> 3064.0987 | E13: =MAX(C13-D13,0) -> 2115.9265 | F13: =Supuestos!B31 -> 55 | G13: =H13+I13+J13 -> 52883865 | H13: =B13*Supuestos!B16*Supuestos!B8 -> 33653369 | I13: =B13*Supuestos!B17*Supuestos!B8 -> 14422872 | J13: =B13*Supuestos!B18*Supuestos!B8 -> 4807624.1 | K13: =B13*Supuestos!B21*Supuestos!B8 -> 3846099.3 | L13: =Supuestos!B22+Supuestos!B23+Supuestos!B24+Supuestos!B25 -> 25000 | M13: =Supuestos!B26 -> 6000 | N13: =N12*(1+Supuestos!B12) -> 55153.776 | O13: =K13+L13+M13+N13 -> 3932253.1 | P13: =G13-O13 -> 48951612 | Q13: =IF(B13*Supuestos!B8>0,P13/(B13*Supuestos!B8),0) -> 50.910399 | R13: =IF(C13>0,N13/C13,0) -> 10.647395 | S13: =IF(G13>0,P13/G13,0) -> 0.92564361
A14: 11 | B14: =MIN(Supuestos!B5,B13*(1+Supuestos!B6+Supuestos!B7)+D14) -> 37438.02 | C14: =B13*(Supuestos!B6+Supuestos!B7)+D14 -> 5808.9141 | D14: =IF(Supuestos!B13>0,N14/Supuestos!B13,0) -> 3278.5856 | E14: =MAX(C14-D14,0) -> 2530.3285 | F14: =Supuestos!B31 -> 55 | G14: =H14+I14+J14 -> 62596369 | H14: =B14*Supuestos!B16*Supuestos!B8 -> 39834053 | I14: =B14*Supuestos!B17*Supuestos!B8 -> 17071737 | J14: =B14*Supuestos!B18*Supuestos!B8 -> 5690579 | K14: =B14*Supuestos!B21*Supuestos!B8 -> 4552463.2 | L14: =Supuestos!B22+Supuestos!B23+Supuestos!B24+Supuestos!B25 -> 25000 | M14: =Supuestos!B26 -> 6000 | N14: =N13*(1+Supuestos!B12) -> 59014.541 | O14: =K14+L14+M14+N14 -> 4642477.8 | P14: =G14-O14 -> 57953892 | Q14: =IF(B14*Supuestos!B8>0,P14/(B14*Supuestos!B8),0) -> 50.920909 | R14: =IF(C14>0,N14/C14,0) -> 10.159307 | S14: =IF(G14>0,P14/G14,0) -> 0.92583471
A15: 12 | B15: =MIN(Supuestos!B5,B14*(1+Supuestos!B6+Supuestos!B7)+D15) -> 43941.148 | C15: =B14*(Supuestos!B6+Supuestos!B7)+D15 -> 6503.1282 | D15: =IF(Supuestos!B13>0,N15/Supuestos!B13,0) -> 3508.0866 | E15: =MAX(C15-D15,0) -> 2995.0416 | F15: =Supuestos!B31 -> 55 | G15: =H15+I15+J15 -> 73469600 | H15: =B15*Supuestos!B16*Supuestos!B8 -> 46753382 | I15: =B15*Supuestos!B17*Supuestos!B8 -> 20037164 | J15: =B15*Supuestos!B18*Supuestos!B8 -> 6679054.5 | K15: =B15*Supuestos!B21*Supuestos!B8 -> 5343243.6 | L15: =Supuestos!B22+Supuestos!B23+Supuestos!B24+Supuestos!B25 -> 25000 | M15: =Supuestos!B26 -> 6000 | N15: =N14*(1+Supuestos!B12) -> 63145.559 | O15: =K15+L15+M15+N15 -> 5437389.2 | P15: =G15-O15 -> 68032211 | Q15: =IF(B15*Supuestos!B8>0,P15/(B15*Supuestos!B8),0) -> 50.929522 | R15: =IF(C15>0,N15/C15,0) -> 9.7100283 | S15: =IF(G15>0,P15/G15,0) -> 0.92599131
A16: 13 | B16: =MIN(Supuestos!B5,B15*(1+Supuestos!B6+Supuestos!B7)+D16) -> 51210.093 | C16: =B15*(Supuestos!B6+Supuestos!B7)+D16 -> 7268.9445 | D16: =IF(Supuestos!B13>0,N16/Supuestos!B13,0) -> 3753.6526 | E16: =MAX(C16-D16,0) -> 3515.2919 | F16: =Supuestos!B31 -> 55 | G16: =H16+I16+J16 -> 85623275 | H16: =B16*Supuestos!B16*Supuestos!B8 -> 54487539 | I16: =B16*Supuestos!B17*Supuestos!B8 -> 23351802 | J16: =B16*Supuestos!B18*Supuestos!B8 -> 7783934.1 | K16: =B16*Supuestos!B21*Supuestos!B8 -> 6227147.3 | L16: =Supuestos!B22+Supuestos!B23+Supuestos!B24+Supuestos!B25 -> 25000 | M16: =Supuestos!B26 -> 6000 | N16: =N15*(1+Supuestos!B12) -> 67565.748 | O16: =K16+L16+M16+N16 -> 6325713 | P16: =G16-O16 -> 79297562 | Q16: =IF(B16*Supuestos!B8>0,P16/(B16*Supuestos!B8),0) -> 50.936686 | R16: =IF(C16>0,N16/C16,0) -> 9.295125 | S16: =IF(G16>0,P16/G16,0) -> 0.92612157
A17: 14 | B17: =MIN(Supuestos!B5,B16*(1+Supuestos!B6+Supuestos!B7)+D17) -> 59323.308 | C17: =B16*(Supuestos!B6+Supuestos!B7)+D17 -> 8113.2157 | D17: =IF(Supuestos!B13>0,N17/Supuestos!B13,0) -> 4016.4083 | E17: =MAX(C17-D17,0) -> 4096.8074 | F17: =Supuestos!B31 -> 55 | G17: =H17+I17+J17 -> 99188572 | H17: =B17*Supuestos!B16*Supuestos!B8 -> 63120000 | I17: =B17*Supuestos!B17*Supuestos!B8 -> 27051429 | J17: =B17*Supuestos!B18*Supuestos!B8 -> 9017142.9 | K17: =B17*Supuestos!B21*Supuestos!B8 -> 7213714.3 | L17: =Supuestos!B22+Supuestos!B23+Supuestos!B24+Supuestos!B25 -> 25000 | M17: =Supuestos!B26 -> 6000 | N17: =N16*(1+Supuestos!B12) -> 72295.35 | O17: =K17+L17+M17+N17 -> 7317009.7 | P17: =G17-O17 -> 91871562 | Q17: =IF(B17*Supuestos!B8>0,P17/(B17*Supuestos!B8),0) -> 50.942723 | R17: =IF(C17>0,N17/C17,0) -> 8.9108132 | S17: =IF(G17>0,P17/G17,0) -> 0.92623132
A18: 15 | B18: =MIN(Supuestos!B5,B17*(1+Supuestos!B6+Supuestos!B7)+D18) -> 68366.73 | C18: =B17*(Supuestos!B6+Supuestos!B7)+D18 -> 9043.4216 | D18: =IF(Supuestos!B13>0,N18/Supuestos!B13,0) -> 4297.5569 | E18: =MAX(C18-D18,0) -> 4745.8647 | F18: =Supuestos!B31 -> 55 | G18: =H18+I18+J18 -> 1.1430917e+08 | H18: =B18*Supuestos!B16*Supuestos!B8 -> 72742201 | I18: =B18*Supuestos!B17*Supuestos!B8 -> 31175229 | J18: =B18*Supuestos!B18*Supuestos!B8 -> 10391743 | K18: =B18*Supuestos!B21*Supuestos!B8 -> 8313394.4 | L18: =Supuestos!B22+Supuestos!B23+Supuestos!B24+Supuestos!B25 -> 25000 | M18: =Supuestos!B26 -> 6000 | N18: =N17*(1+Supuestos!B12) -> 77356.025 | O18: =K18+L18+M18+N18 -> 8421750.4 | P18: =G18-O18 -> 1.0588742e+08 | Q18: =IF(B18*Supuestos!B8>0,P18/(B18*Supuestos!B8),0) -> 50.947864 | R18: =IF(C18>0,N18/C18,0) -> 8.5538448 | S18: =IF(G18>0,P18/G18,0) -> 0.92632481
A19: 16 | B19: =MIN(Supuestos!B5,B18*(1+Supuestos!B6+Supuestos!B7)+D19) -> 78434.454 | C19: =B18*(Supuestos!B6+Supuestos!B7)+D19 -> 10067.724 | D19: =IF(Supuestos!B13>0,N19/Supuestos!B13,0) -> 4598.3859 | E19: =MAX(C19-D19,0) -> 5469.3384 | F19: =Supuestos!B31 -> 55 | G19: =H19+I19+J19 -> 1.3114241e+08 | H19: =B19*Supuestos!B16*Supuestos!B8 -> 83454259 | I19: =B19*Supuestos!B17*Supuestos!B8 -> 35766111 | J19: =B19*Supuestos!B18*Supuestos!B8 -> 11922037 | K19: =B19*Supuestos!B21*Supuestos!B8 -> 9537629.6 | L19: =Supuestos!B22+Supuestos!B23+Supuestos!B24+Supuestos!B25 -> 25000 | M19: =Supuestos!B26 -> 6000 | N19: =N18*(1+Supuestos!B12) -> 82770.946 | O19: =K19+L19+M19+N19 -> 9651400.6 | P19: =G19-O19 -> 1.2149101e+08 | Q19: =IF(B19*Supuestos!B8>0,P19/(B19*Supuestos!B8),0) -> 50.952285 | R19: =IF(C19>0,N19/C19,0) -> 8.2214157 | S19: =IF(G19>0,P19/G19,0) -> 0.92640519
A20: 17 | B20: =MIN(Supuestos!B5,B19*(1+Supuestos!B6+Supuestos!B7)+D20) -> 89629.484 | C20: =B19*(Supuestos!B6+Supuestos!B7)+D20 -> 11195.029 | D20: =IF(Supuestos!B13>0,N20/Supuestos!B13,0) -> 4920.2729 | E20: =MAX(C20-D20,0) -> 6274.7563 | F20: =Supuestos!B31 -> 55 | G20: =H20+I20+J20 -> 1.498605e+08 | H20: =B20*Supuestos!B16*Supuestos!B8 -> 95365770 | I20: =B20*Supuestos!B17*Supuestos!B8 -> 40871044 | J20: =B20*Supuestos!B18*Supuestos!B8 -> 13623681 | K20: =B20*Supuestos!B21*Supuestos!B8 -> 10898945 | L20: =Supuestos!B22+Supuestos!B23+Supuestos!B24+Supuestos!B25 -> 25000 | M20: =Supuestos!B26 -> 6000 | N20: =N19*(1+Supuestos!B12) -> 88564.912 | O20: =K20+L20+M20+N20 -> 11018510 | P20: =G20-O20 -> 1.3884199e+08 | Q20: =IF(B20*Supuestos!B8>0,P20/(B20*Supuestos!B8),0) -> 50.956119 | R20: =IF(C20>0,N20/C20,0) -> 7.9110925 | S20: =IF(G20>0,P20/G20,0) -> 0.92647489
A21: 18 | B21: =MIN(Supuestos!B5,B20*(1+Supuestos!B6+Supuestos!B7)+D21) -> 100000 | C21: =B20*(Supuestos!B6+Supuestos!B7)+D21 -> 12435.051 | D21: =IF(Supuestos!B13>0,N21/Supuestos!B13,0) -> 5264.692 | E21: =MAX(C21-D21,0) -> 7170.3587 | F21: =Supuestos!B31 -> 55 | G21: =H21+I21+J21 -> 167200000 | H21: =B21*Supuestos!B16*Supuestos!B8 -> 106400000 | I21: =B21*Supuestos!B17*Supuestos!B8 -> 45600000 | J21: =B21*Supuestos!B18*Supuestos!B8 -> 15200000 | K21: =B21*Supuestos!B21*Supuestos!B8 -> 12160000 | L21: =Supuestos!B22+Supuestos!B23+Supuestos!B24+Supuestos!B25 -> 25000 | M21: =Supuestos!B26 -> 6000 | N21: =N20*(1+Supuestos!B12) -> 94764.456 | O21: =K21+L21+M21+N21 -> 12285764 | P21: =G21-O21 -> 1.5491424e+08 | Q21: =IF(B21*Supuestos!B8>0,P21/(B21*Supuestos!B8),0) -> 50.95863 | R21: =IF(C21>0,N21/C21,0) -> 7.6207535 | S21: =IF(G21>0,P21/G21,0) -> 0.92652055
A22: 19 | B22: =MIN(Supuestos!B5,B21*(1+Supuestos!B6+Supuestos!B7)+D22) -> 100000 | C22: =B21*(Supuestos!B6+Supuestos!B7)+D22 -> 13633.22 | D22: =IF(Supuestos!B13>0,N22/Supuestos!B13,0) -> 5633.2205 | E22: =MAX(C22-D22,0) -> 8000 | F22: =Supuestos!B31 -> 55 | G22: =H22+I22+J22 -> 167200000 | H22: =B22*Supuestos!B16*Supuestos!B8 -> 106400000 | I22: =B22*Supuestos!B17*Supuestos!B8 -> 45600000 | J22: =B22*Supuestos!B18*Supuestos!B8 -> 15200000 | K22: =B22*Supuestos!B21*Supuestos!B8 -> 12160000 | L22: =Supuestos!B22+Supuestos!B23+Supuestos!B24+Supuestos!B25 -> 25000 | M22: =Supuestos!B26 -> 6000 | N22: =N21*(1+Supuestos!B12) -> 101397.97 | O22: =K22+L22+M22+N22 -> 12292398 | P22: =G22-O22 -> 1.549076e+08 | Q22: =IF(B22*Supuestos!B8>0,P22/(B22*Supuestos!B8),0) -> 50.956448 | R22: =IF(C22>0,N22/C22,0) -> 7.4375654 | S22: =IF(G22>0,P22/G22,0) -> 0.92648087
A23: 20 | B23: =MIN(Supuestos!B5,B22*(1+Supuestos!B6+Supuestos!B7)+D23) -> 100000 | C23: =B22*(Supuestos!B6+Supuestos!B7)+D23 -> 14027.546 | D23: =IF(Supuestos!B13>0,N23/Supuestos!B13,0) -> 6027.5459 | E23: =MAX(C23-D23,0) -> 8000 | F23: =Supuestos!B31 -> 55 | G23: =H23+I23+J23 -> 167200000 | H23: =B23*Supuestos!B16*Supuestos!B8 -> 106400000 | I23: =B23*Supuestos!B17*Supuestos!B8 -> 45600000 | J23: =B23*Supuestos!B18*Supuestos!B8 -> 15200000 | K23: =B23*Supuestos!B21*Supuestos!B8 -> 12160000 | L23: =Supuestos!B22+Supuestos!B23+Supuestos!B24+Supuestos!B25 -> 25000 | M23: =Supuestos!B26 -> 6000 | N23: =N22*(1+Supuestos!B12) -> 108495.83 | O23: =K23+L23+M23+N23 -> 12299496 | P23: =G23-O23 -> 1.549005e+08 | Q23: =IF(B23*Supuestos!B8>0,P23/(B23*Supuestos!B8),0) -> 50.954113 | R23: =IF(C23>0,N23/C23,0) -> 7.7344838 | S23: =IF(G23>0,P23/G23,0) -> 0.92643842
A24: 21 | B24: =MIN(Supuestos!B5,B23*(1+Supuestos!B6+Supuestos!B7)+D24) -> 100000 | C24: =B23*(Supuestos!B6+Supuestos!B7)+D24 -> 14449.474 | D24: =IF(Supuestos!B13>0,N24/Supuestos!B13,0) -> 6449.4741 | E24: =MAX(C24-D24,0) -> 8000 | F24: =Supuestos!B31 -> 55 | G24: =H24+I24+J24 -> 167200000 | H24: =B24*Supuestos!B16*Supuestos!B8 -> 106400000 | I24: =B24*Supuestos!B17*Supuestos!B8 -> 45600000 | J24: =B24*Supuestos!B18*Supuestos!B8 -> 15200000 | K24: =B24*Supuestos!B21*Supuestos!B8 -> 12160000 | L24: =Supuestos!B22+Supuestos!B23+Supuestos!B24+Supuestos!B25 -> 25000 | M24: =Supuestos!B26 -> 6000 | N24: =N23*(1+Supuestos!B12) -> 116090.53 | O24: =K24+L24+M24+N24 -> 12307091 | P24: =G24-O24 -> 1.5489291e+08 | Q24: =IF(B24*Supuestos!B8>0,P24/(B24*Supuestos!B8),0) -> 50.951615 | R24: =IF(C24>0,N24/C24,0) -> 8.0342394 | S24: =IF(G24>0,P24/G24,0) -> 0.926393
A25: 22 | B25: =MIN(Supuestos!B5,B24*(1+Supuestos!B6+Supuestos!B7)+D25) -> 100000 | C25: =B24*(Supuestos!B6+Supuestos!B7)+D25 -> 14900.937 | D25: =IF(Supuestos!B13>0,N25/Supuestos!B13,0) -> 6900.9373 | E25: =MAX(C25-D25,0) -> 8000 | F25: =Supuestos!B31 -> 55 | G25: =H25+I25+J25 -> 167200000 | H25: =B25*Supuestos!B16*Supuestos!B8 -> 106400000 | I25: =B25*Supuestos!B17*Supuestos!B8 -> 45600000 | J25: =B25*Supuestos!B18*Supuestos!B8 -> 15200000 | K25: =B25*Supuestos!B21*Supuestos!B8 -> 12160000 | L25: =Supuestos!B22+Supuestos!B23+Supuestos!B24+Supuestos!B25 -> 25000 | M25: =Supuestos!B26 -> 6000 | N25: =N24*(1+Supuestos!B12) -> 124216.87 | O25: =K25+L25+M25+N25 -> 12315217 | P25: =G25-O25 -> 1.5488478e+08 | Q25: =IF(B25*Supuestos!B8>0,P25/(B25*Supuestos!B8),0) -> 50.948942 | R25: =IF(C25>0,N25/C25,0) -> 8.3361784 | S25: =IF(G25>0,P25/G25,0) -> 0.9263444
A26: 23 | B26: =MIN(Supuestos!B5,B25*(1+Supuestos!B6+Supuestos!B7)+D26) -> 100000 | C26: =B25*(Supuestos!B6+Supuestos!B7)+D26 -> 15384.003 | D26: =IF(Supuestos!B13>0,N26/Supuestos!B13,0) -> 7384.0029 | E26: =MAX(C26-D26,0) -> 8000 | F26: =Supuestos!B31 -> 55 | G26: =H26+I26+J26 -> 167200000 | H26: =B26*Supuestos!B16*Supuestos!B8 -> 106400000 | I26: =B26*Supuestos!B17*Supuestos!B8 -> 45600000 | J26: =B26*Supuestos!B18*Supuestos!B8 -> 15200000 | K26: =B26*Supuestos!B21*Supuestos!B8 -> 12160000 | L26: =Supuestos!B22+Supuestos!B23+Supuestos!B24+Supuestos!B25 -> 25000 | M26: =Supuestos!B26 -> 6000 | N26: =N25*(1+Supuestos!B12) -> 132912.05 | O26: =K26+L26+M26+N26 -> 12323912 | P26: =G26-O26 -> 1.5487609e+08 | Q26: =IF(B26*Supuestos!B8>0,P26/(B26*Supuestos!B8),0) -> 50.946082 | R26: =IF(C26>0,N26/C26,0) -> 8.6396274 | S26: =IF(G26>0,P26/G26,0) -> 0.92629239
A27: 24 | B27: =MIN(Supuestos!B5,B26*(1+Supuestos!B6+Supuestos!B7)+D27) -> 100000 | C27: =B26*(Supuestos!B6+Supuestos!B7)+D27 -> 15900.883 | D27: =IF(Supuestos!B13>0,N27/Supuestos!B13,0) -> 7900.8831 | E27: =MAX(C27-D27,0) -> 8000 | F27: =Supuestos!B31 -> 55 | G27: =H27+I27+J27 -> 167200000 | H27: =B27*Supuestos!B16*Supuestos!B8 -> 106400000 | I27: =B27*Supuestos!B17*Supuestos!B8 -> 45600000 | J27: =B27*Supuestos!B18*Supuestos!B8 -> 15200000 | K27: =B27*Supuestos!B21*Supuestos!B8 -> 12160000 | L27: =Supuestos!B22+Supuestos!B23+Supuestos!B24+Supuestos!B25 -> 25000 | M27: =Supuestos!B26 -> 6000 | N27: =N26*(1+Supuestos!B12) -> 142215.9 | O27: =K27+L27+M27+N27 -> 12333216 | P27: =G27-O27 -> 1.5486678e+08 | Q27: =IF(B27*Supuestos!B8>0,P27/(B27*Supuestos!B8),0) -> 50.943021 | R27: =IF(C27>0,N27/C27,0) -> 8.9438992 | S27: =IF(G27>0,P27/G27,0) -> 0.92623675
A28: 25 | B28: =MIN(Supuestos!B5,B27*(1+Supuestos!B6+Supuestos!B7)+D28) -> 100000 | C28: =B27*(Supuestos!B6+Supuestos!B7)+D28 -> 16453.945 | D28: =IF(Supuestos!B13>0,N28/Supuestos!B13,0) -> 8453.9449 | E28: =MAX(C28-D28,0) -> 8000 | F28: =Supuestos!B31 -> 55 | G28: =H28+I28+J28 -> 167200000 | H28: =B28*Supuestos!B16*Supuestos!B8 -> 106400000 | I28: =B28*Supuestos!B17*Supuestos!B8 -> 45600000 | J28: =B28*Supuestos!B18*Supuestos!B8 -> 15200000 | K28: =B28*Supuestos!B21*Supuestos!B8 -> 12160000 | L28: =Supuestos!B22+Supuestos!B23+Supuestos!B24+Supuestos!B25 -> 25000 | M28: =Supuestos!B26 -> 6000 | N28: =N27*(1+Supuestos!B12) -> 152171.01 | O28: =K28+L28+M28+N28 -> 12343171 | P28: =G28-O28 -> 1.5485683e+08 | Q28: =IF(B28*Supuestos!B8>0,P28/(B28*Supuestos!B8),0) -> 50.939746 | R28: =IF(C28>0,N28/C28,0) -> 9.2482994 | S28: =IF(G28>0,P28/G28,0) -> 0.92617721
A29: 26 | B29: =MIN(Supuestos!B5,B28*(1+Supuestos!B6+Supuestos!B7)+D29) -> 100000 | C29: =B28*(Supuestos!B6+Supuestos!B7)+D29 -> 17045.721 | D29: =IF(Supuestos!B13>0,N29/Supuestos!B13,0) -> 9045.7211 | E29: =MAX(C29-D29,0) -> 8000 | F29: =Supuestos!B31 -> 55 | G29: =H29+I29+J29 -> 167200000 | H29: =B29*Supuestos!B16*Supuestos!B8 -> 106400000 | I29: =B29*Supuestos!B17*Supuestos!B8 -> 45600000 | J29: =B29*Supuestos!B18*Supuestos!B8 -> 15200000 | K29: =B29*Supuestos!B21*Supuestos!B8 -> 12160000 | L29: =Supuestos!B22+Supuestos!B23+Supuestos!B24+Supuestos!B25 -> 25000 | M29: =Supuestos!B26 -> 6000 | N29: =N28*(1+Supuestos!B12) -> 162822.98 | O29: =K29+L29+M29+N29 -> 12353823 | P29: =G29-O29 -> 1.5484618e+08 | Q29: =IF(B29*Supuestos!B8>0,P29/(B29*Supuestos!B8),0) -> 50.936242 | R29: =IF(C29>0,N29/C29,0) -> 9.5521321 | S29: =IF(G29>0,P29/G29,0) -> 0.9261135
A30: 27 | B30: =MIN(Supuestos!B5,B29*(1+Supuestos!B6+Supuestos!B7)+D30) -> 100000 | C30: =B29*(Supuestos!B6+Supuestos!B7)+D30 -> 17678.922 | D30: =IF(Supuestos!B13>0,N30/Supuestos!B13,0) -> 9678.9215 | E30: =MAX(C30-D30,0) -> 8000 | F30: =Supuestos!B31 -> 55 | G30: =H30+I30+J30 -> 167200000 | H30: =B30*Supuestos!B16*Supuestos!B8 -> 106400000 | I30: =B30*Supuestos!B17*Supuestos!B8 -> 45600000 | J30: =B30*Supuestos!B18*Supuestos!B8 -> 15200000 | K30: =B30*Supuestos!B21*Supuestos!B8 -> 12160000 | L30: =Supuestos!B22+Supuestos!B23+Supuestos!B24+Supuestos!B25 -> 25000 | M30: =Supuestos!B26 -> 6000 | N30: =N29*(1+Supuestos!B12) -> 174220.59 | O30: =K30+L30+M30+N30 -> 12365221 | P30: =G30-O30 -> 1.5483478e+08 | Q30: =IF(B30*Supuestos!B8>0,P30/(B30*Supuestos!B8),0) -> 50.932493 | R30: =IF(C30>0,N30/C30,0) -> 9.8547068 | S30: =IF(G30>0,P30/G30,0) -> 0.92604533
A31: 28 | B31: =MIN(Supuestos!B5,B30*(1+Supuestos!B6+Supuestos!B7)+D31) -> 100000 | C31: =B30*(Supuestos!B6+Supuestos!B7)+D31 -> 18356.446 | D31: =IF(Supuestos!B13>0,N31/Supuestos!B13,0) -> 10356.446 | E31: =MAX(C31-D31,0) -> 8000 | F31: =Supuestos!B31 -> 55 | G31: =H31+I31+J31 -> 167200000 | H31: =B31*Supuestos!B16*Supuestos!B8 -> 106400000 | I31: =B31*Supuestos!B17*Supuestos!B8 -> 45600000 | J31: =B31*Supuestos!B18*Supuestos!B8 -> 15200000 | K31: =B31*Supuestos!B21*Supuestos!B8 -> 12160000 | L31: =Supuestos!B22+Supuestos!B23+Supuestos!B24+Supuestos!B25 -> 25000 | M31: =Supuestos!B26 -> 6000 | N31: =N30*(1+Supuestos!B12) -> 186416.03 | O31: =K31+L31+M31+N31 -> 12377416 | P31: =G31-O31 -> 1.5482258e+08 | Q31: =IF(B31*Supuestos!B8>0,P31/(B31*Supuestos!B8),0) -> 50.928482 | R31: =IF(C31>0,N31/C31,0) -> 10.155344 | S31: =IF(G31>0,P31/G31,0) -> 0.92597239
A32: 29 | B32: =MIN(Supuestos!B5,B31*(1+Supuestos!B6+Supuestos!B7)+D32) -> 100000 | C32: =B31*(Supuestos!B6+Supuestos!B7)+D32 -> 19081.397 | D32: =IF(Supuestos!B13>0,N32/Supuestos!B13,0) -> 11081.397 | E32: =MAX(C32-D32,0) -> 8000 | F32: =Supuestos!B31 -> 55 | G32: =H32+I32+J32 -> 167200000 | H32: =B32*Supuestos!B16*Supuestos!B8 -> 106400000 | I32: =B32*Supuestos!B17*Supuestos!B8 -> 45600000 | J32: =B32*Supuestos!B18*Supuestos!B8 -> 15200000 | K32: =B32*Supuestos!B21*Supuestos!B8 -> 12160000 | L32: =Supuestos!B22+Supuestos!B23+Supuestos!B24+Supuestos!B25 -> 25000 | M32: =Supuestos!B26 -> 6000 | N32: =N31*(1+Supuestos!B12) -> 199465.15 | O32: =K32+L32+M32+N32 -> 12390465 | P32: =G32-O32 -> 1.5480953e+08 | Q32: =IF(B32*Supuestos!B8>0,P32/(B32*Supuestos!B8),0) -> 50.924189 | R32: =IF(C32>0,N32/C32,0) -> 10.453383 | S32: =IF(G32>0,P32/G32,0) -> 0.92589435
A33: 30 | B33: =MIN(Supuestos!B5,B32*(1+Supuestos!B6+Supuestos!B7)+D33) -> 100000 | C33: =B32*(Supuestos!B6+Supuestos!B7)+D33 -> 19857.095 | D33: =IF(Supuestos!B13>0,N33/Supuestos!B13,0) -> 11857.095 | E33: =MAX(C33-D33,0) -> 8000 | F33: =Supuestos!B31 -> 55 | G33: =H33+I33+J33 -> 167200000 | H33: =B33*Supuestos!B16*Supuestos!B8 -> 106400000 | I33: =B33*Supuestos!B17*Supuestos!B8 -> 45600000 | J33: =B33*Supuestos!B18*Supuestos!B8 -> 15200000 | K33: =B33*Supuestos!B21*Supuestos!B8 -> 12160000 | L33: =Supuestos!B22+Supuestos!B23+Supuestos!B24+Supuestos!B25 -> 25000 | M33: =Supuestos!B26 -> 6000 | N33: =N32*(1+Supuestos!B12) -> 213427.71 | O33: =K33+L33+M33+N33 -> 12404428 | P33: =G33-O33 -> 1.5479557e+08 | Q33: =IF(B33*Supuestos!B8>0,P33/(B33*Supuestos!B8),0) -> 50.919596 | R33: =IF(C33>0,N33/C33,0) -> 10.748184 | S33: =IF(G33>0,P33/G33,0) -> 0.92581084
A34: 31 | B34: =MIN(Supuestos!B5,B33*(1+Supuestos!B6+Supuestos!B7)+D34) -> 100000 | C34: =B33*(Supuestos!B6+Supuestos!B7)+D34 -> 20687.092 | D34: =IF(Supuestos!B13>0,N34/Supuestos!B13,0) -> 12687.092 | E34: =MAX(C34-D34,0) -> 8000 | F34: =Supuestos!B31 -> 55 | G34: =H34+I34+J34 -> 167200000 | H34: =B34*Supuestos!B16*Supuestos!B8 -> 106400000 | I34: =B34*Supuestos!B17*Supuestos!B8 -> 45600000 | J34: =B34*Supuestos!B18*Supuestos!B8 -> 15200000 | K34: =B34*Supuestos!B21*Supuestos!B8 -> 12160000 | L34: =Supuestos!B22+Supuestos!B23+Supuestos!B24+Supuestos!B25 -> 25000 | M34: =Supuestos!B26 -> 6000 | N34: =N33*(1+Supuestos!B12) -> 228367.65 | O34: =K34+L34+M34+N34 -> 12419368 | P34: =G34-O34 -> 1.5478063e+08 | Q34: =IF(B34*Supuestos!B8>0,P34/(B34*Supuestos!B8),0) -> 50.914682 | R34: =IF(C34>0,N34/C34,0) -> 11.039138 | S34: =IF(G34>0,P34/G34,0) -> 0.92572149
A35: 32 | B35: =MIN(Supuestos!B5,B34*(1+Supuestos!B6+Supuestos!B7)+D35) -> 100000 | C35: =B34*(Supuestos!B6+Supuestos!B7)+D35 -> 21575.188 | D35: =IF(Supuestos!B13>0,N35/Supuestos!B13,0) -> 13575.188 | E35: =MAX(C35-D35,0) -> 8000 | F35: =Supuestos!B31 -> 55 | G35: =H35+I35+J35 -> 167200000 | H35: =B35*Supuestos!B16*Supuestos!B8 -> 106400000 | I35: =B35*Supuestos!B17*Supuestos!B8 -> 45600000 | J35: =B35*Supuestos!B18*Supuestos!B8 -> 15200000 | K35: =B35*Supuestos!B21*Supuestos!B8 -> 12160000 | L35: =Supuestos!B22+Supuestos!B23+Supuestos!B24+Supuestos!B25 -> 25000 | M35: =Supuestos!B26 -> 6000 | N35: =N34*(1+Supuestos!B12) -> 244353.39 | O35: =K35+L35+M35+N35 -> 12435353 | P35: =G35-O35 -> 1.5476465e+08 | Q35: =IF(B35*Supuestos!B8>0,P35/(B35*Supuestos!B8),0) -> 50.909423 | R35: =IF(C35>0,N35/C35,0) -> 11.325667 | S35: =IF(G35>0,P35/G35,0) -> 0.92562588
A36: 33 | B36: =MIN(Supuestos!B5,B35*(1+Supuestos!B6+Supuestos!B7)+D36) -> 100000 | C36: =B35*(Supuestos!B6+Supuestos!B7)+D36 -> 22525.451 | D36: =IF(Supuestos!B13>0,N36/Supuestos!B13,0) -> 14525.451 | E36: =MAX(C36-D36,0) -> 8000 | F36: =Supuestos!B31 -> 55 | G36: =H36+I36+J36 -> 167200000 | H36: =B36*Supuestos!B16*Supuestos!B8 -> 106400000 | I36: =B36*Supuestos!B17*Supuestos!B8 -> 45600000 | J36: =B36*Supuestos!B18*Supuestos!B8 -> 15200000 | K36: =B36*Supuestos!B21*Supuestos!B8 -> 12160000 | L36: =Supuestos!B22+Supuestos!B23+Supuestos!B24+Supuestos!B25 -> 25000 | M36: =Supuestos!B26 -> 6000 | N36: =N35*(1+Supuestos!B12) -> 261458.12 | O36: =K36+L36+M36+N36 -> 12452458 | P36: =G36-O36 -> 1.5474754e+08 | Q36: =IF(B36*Supuestos!B8>0,P36/(B36*Supuestos!B8),0) -> 50.903797 | R36: =IF(C36>0,N36/C36,0) -> 11.607231 | S36: =IF(G36>0,P36/G36,0) -> 0.92552358
A37: 34 | B37: =MIN(Supuestos!B5,B36*(1+Supuestos!B6+Supuestos!B7)+D37) -> 100000 | C37: =B36*(Supuestos!B6+Supuestos!B7)+D37 -> 23542.233 | D37: =IF(Supuestos!B13>0,N37/Supuestos!B13,0) -> 15542.233 | E37: =MAX(C37-D37,0) -> 8000 | F37: =Supuestos!B31 -> 55 | G37: =H37+I37+J37 -> 167200000 | H37: =B37*Supuestos!B16*Supuestos!B8 -> 106400000 | I37: =B37*Supuestos!B17*Supuestos!B8 -> 45600000 | J37: =B37*Supuestos!B18*Supuestos!B8 -> 15200000 | K37: =B37*Supuestos!B21*Supuestos!B8 -> 12160000 | L37: =Supuestos!B22+Supuestos!B23+Supuestos!B24+Supuestos!B25 -> 25000 | M37: =Supuestos!B26 -> 6000 | N37: =N36*(1+Supuestos!B12) -> 279760.19 | O37: =K37+L37+M37+N37 -> 12470760 | P37: =G37-O37 -> 1.5472924e+08 | Q37: =IF(B37*Supuestos!B8>0,P37/(B37*Supuestos!B8),0) -> 50.897776 | R37: =IF(C37>0,N37/C37,0) -> 11.883333 | S37: =IF(G37>0,P37/G37,0) -> 0.92541411
A38: 35 | B38: =MIN(Supuestos!B5,B37*(1+Supuestos!B6+Supuestos!B7)+D38) -> 100000 | C38: =B37*(Supuestos!B6+Supuestos!B7)+D38 -> 24630.189 | D38: =IF(Supuestos!B13>0,N38/Supuestos!B13,0) -> 16630.189 | E38: =MAX(C38-D38,0) -> 8000 | F38: =Supuestos!B31 -> 55 | G38: =H38+I38+J38 -> 167200000 | H38: =B38*Supuestos!B16*Supuestos!B8 -> 106400000 | I38: =B38*Supuestos!B17*Supuestos!B8 -> 45600000 | J38: =B38*Supuestos!B18*Supuestos!B8 -> 15200000 | K38: =B38*Supuestos!B21*Supuestos!B8 -> 12160000 | L38: =Supuestos!B22+Supuestos!B23+Supuestos!B24+Supuestos!B25 -> 25000 | M38: =Supuestos!B26 -> 6000 | N38: =N37*(1+Supuestos!B12) -> 299343.41 | O38: =K38+L38+M38+N38 -> 12490343 | P38: =G38-O38 -> 1.5470966e+08 | Q38: =IF(B38*Supuestos!B8>0,P38/(B38*Supuestos!B8),0) -> 50.891334 | R38: =IF(C38>0,N38/C38,0) -> 12.153516 | S38: =IF(G38>0,P38/G38,0) -> 0.92529699
A39: 36 | B39: =MIN(Supuestos!B5,B38*(1+Supuestos!B6+Supuestos!B7)+D39) -> 100000 | C39: =B38*(Supuestos!B6+Supuestos!B7)+D39 -> 25794.302 | D39: =IF(Supuestos!B13>0,N39/Supuestos!B13,0) -> 17794.302 | E39: =MAX(C39-D39,0) -> 8000 | F39: =Supuestos!B31 -> 55 | G39: =H39+I39+J39 -> 167200000 | H39: =B39*Supuestos!B16*Supuestos!B8 -> 106400000 | I39: =B39*Supuestos!B17*Supuestos!B8 -> 45600000 | J39: =B39*Supuestos!B18*Supuestos!B8 -> 15200000 | K39: =B39*Supuestos!B21*Supuestos!B8 -> 12160000 | L39: =Supuestos!B22+Supuestos!B23+Supuestos!B24+Supuestos!B25 -> 25000 | M39: =Supuestos!B26 -> 6000 | N39: =N38*(1+Supuestos!B12) -> 320297.44 | O39: =K39+L39+M39+N39 -> 12511297 | P39: =G39-O39 -> 1.546887e+08 | Q39: =IF(B39*Supuestos!B8>0,P39/(B39*Supuestos!B8),0) -> 50.884442 | R39: =IF(C39>0,N39/C39,0) -> 12.417372 | S39: =IF(G39>0,P39/G39,0) -> 0.92517167
A40: 37 | B40: =MIN(Supuestos!B5,B39*(1+Supuestos!B6+Supuestos!B7)+D40) -> 100000 | C40: =B39*(Supuestos!B6+Supuestos!B7)+D40 -> 27039.904 | D40: =IF(Supuestos!B13>0,N40/Supuestos!B13,0) -> 19039.904 | E40: =MAX(C40-D40,0) -> 8000 | F40: =Supuestos!B31 -> 55 | G40: =H40+I40+J40 -> 167200000 | H40: =B40*Supuestos!B16*Supuestos!B8 -> 106400000 | I40: =B40*Supuestos!B17*Supuestos!B8 -> 45600000 | J40: =B40*Supuestos!B18*Supuestos!B8 -> 15200000 | K40: =B40*Supuestos!B21*Supuestos!B8 -> 12160000 | L40: =Supuestos!B22+Supuestos!B23+Supuestos!B24+Supuestos!B25 -> 25000 | M40: =Supuestos!B26 -> 6000 | N40: =N39*(1+Supuestos!B12) -> 342718.27 | O40: =K40+L40+M40+N40 -> 12533718 | P40: =G40-O40 -> 1.5466628e+08 | Q40: =IF(B40*Supuestos!B8>0,P40/(B40*Supuestos!B8),0) -> 50.877066 | R40: =IF(C40>0,N40/C40,0) -> 12.674537 | S40: =IF(G40>0,P40/G40,0) -> 0.92503757
A41: 38 | B41: =MIN(Supuestos!B5,B40*(1+Supuestos!B6+Supuestos!B7)+D41) -> 100000 | C41: =B40*(Supuestos!B6+Supuestos!B7)+D41 -> 28372.697 | D41: =IF(Supuestos!B13>0,N41/Supuestos!B13,0) -> 20372.697 | E41: =MAX(C41-D41,0) -> 8000 | F41: =Supuestos!B31 -> 55 | G41: =H41+I41+J41 -> 167200000 | H41: =B41*Supuestos!B16*Supuestos!B8 -> 106400000 | I41: =B41*Supuestos!B17*Supuestos!B8 -> 45600000 | J41: =B41*Supuestos!B18*Supuestos!B8 -> 15200000 | K41: =B41*Supuestos!B21*Supuestos!B8 -> 12160000 | L41: =Supuestos!B22+Supuestos!B23+Supuestos!B24+Supuestos!B25 -> 25000 | M41: =Supuestos!B26 -> 6000 | N41: =N40*(1+Supuestos!B12) -> 366708.54 | O41: =K41+L41+M41+N41 -> 12557709 | P41: =G41-O41 -> 1.5464229e+08 | Q41: =IF(B41*Supuestos!B8>0,P41/(B41*Supuestos!B8),0) -> 50.869175 | R41: =IF(C41>0,N41/C41,0) -> 12.924698 | S41: =IF(G41>0,P41/G41,0) -> 0.92489409
...

Sheet Resumen_Exec
A1: IslaEncantada.com – Resumen ejecutivo del modelo (USD)
A3: Escenario: | B3: Agresivo, realista y optimista
A5: KPI | B5: Mes 1 | C5: Mes 12 | D5: Mes 36 | E5: Mes 60
A6: DAU promedio | B6: =Proyeccion_60m!B4 -> 1500 | C6: =Proyeccion_60m!B15 -> 43941.148 | D6: =Proyeccion_60m!B39 -> 100000 | E6: =Proyeccion_60m!B63 -> 100000
A7: Ingresos totales (USD) | B7: =Proyeccion_60m!G4 -> 2508000 | C7: =Proyeccion_60m!G15 -> 73469600 | D7: =Proyeccion_60m!G39 -> 167200000 | E7: =Proyeccion_60m!G63 -> 167200000
A8: Utilidad mensual (USD) | B8: =Proyeccion_60m!P4 -> 2264600 | C8: =Proyeccion_60m!P15 -> 68032211 | D8: =Proyeccion_60m!P39 -> 1.546887e+08 | E8: =Proyeccion_60m!P63 -> 1.5338433e+08
A9: Margen de utilidad | B9: =Proyeccion_60m!S4 -> 0.90295056 | C9: =Proyeccion_60m!S15 -> 0.92599131 | D9: =Proyeccion_60m!S39 -> 0.92517167 | E9: =Proyeccion_60m!S63 -> 0.91737042
A10: Utilidad por usuario activo 24h (USD) | B10: =Proyeccion_60m!Q4 -> 49.662281 | C10: =Proyeccion_60m!Q15 -> 50.929522 | D10: =Proyeccion_60m!Q39 -> 50.884442 | E10: =Proyeccion_60m!Q63 -> 50.455373
A11: CAC mezclado (USD) | B11: =Proyeccion_60m!R4 -> 20 | C11: =Proyeccion_60m!R15 -> 9.7100283 | D11: =Proyeccion_60m!R39 -> 12.417372 | E11: =Proyeccion_60m!R63 -> 16.534489
